<?xml version="1.0"?>

<robot name="robotic_arm">

    <material name="grey">
        <color rgba="0.5 0.5 0.5 1" />
    </material>

    <material name="blue">
        <color rgba="0 0 0.5 1" />
    </material>


    <link name="base_link">
        <visual>
            <geometry>
                <box size="0.4 0.4 0.1" />
            </geometry>
            <origin xyz="0 0 0.05" rpy="0 0 0" />
            <material name="grey" />
        </visual>
    </link>

    <link name="shoulder_link">
        <visual>
            <geometry>
                <cylinder length="0.5" radius="0.1" />
            </geometry>
            <origin xyz="0 0 0.25" rpy="0 0 0" />
            <material name="blue" />
        </visual>
    </link>

    <joint name="joint1" type="revolute">
        <parent link="base_link" />
        <child link="shoulder_link" />
        <origin xyz="0 0 0.1" rpy="0 0 0" />
        <axis xyz="0 0 1" />
        <limit effort="1000.0" velocity="1.0" lower="-3.14" upper="3.14" />    
    </joint>
</robot>